[2024-03-21T16:51:36.720+0000] {taskinstance.py:1979} INFO - Dependencies all met for dep_context=non-requeueable deps ti=<TaskInstance: spotify_to_s3_data_extraction_v1.sptoify_to_csv scheduled__2024-03-21T15:13:00+00:00 [queued]>
[2024-03-21T16:51:36.777+0000] {taskinstance.py:1979} INFO - Dependencies all met for dep_context=requeueable deps ti=<TaskInstance: spotify_to_s3_data_extraction_v1.sptoify_to_csv scheduled__2024-03-21T15:13:00+00:00 [queued]>
[2024-03-21T16:51:36.778+0000] {taskinstance.py:2193} INFO - Starting attempt 7 of 12
[2024-03-21T16:51:36.906+0000] {taskinstance.py:2217} INFO - Executing <Task(PythonOperator): sptoify_to_csv> on 2024-03-21 15:13:00+00:00
[2024-03-21T16:51:36.960+0000] {standard_task_runner.py:60} INFO - Started process 3268 to run task
[2024-03-21T16:51:36.964+0000] {standard_task_runner.py:87} INFO - Running: ['***', 'tasks', 'run', 'spotify_to_s3_data_extraction_v1', 'sptoify_to_csv', 'scheduled__2024-03-21T15:13:00+00:00', '--job-id', '644', '--raw', '--subdir', 'DAGS_FOLDER/spotify_to_csvs_to_s3.py', '--cfg-path', '/tmp/tmpsphhwj4n']
[2024-03-21T16:51:36.984+0000] {standard_task_runner.py:88} INFO - Job 644: Subtask sptoify_to_csv
[2024-03-21T16:51:37.366+0000] {task_command.py:423} INFO - Running <TaskInstance: spotify_to_s3_data_extraction_v1.sptoify_to_csv scheduled__2024-03-21T15:13:00+00:00 [running]> on host ca1809388db1
[2024-03-21T16:51:37.960+0000] {taskinstance.py:2513} INFO - Exporting env vars: AIRFLOW_CTX_DAG_OWNER='Nathaniel Solomon' AIRFLOW_CTX_DAG_ID='spotify_to_s3_data_extraction_v1' AIRFLOW_CTX_TASK_ID='sptoify_to_csv' AIRFLOW_CTX_EXECUTION_DATE='2024-03-21T15:13:00+00:00' AIRFLOW_CTX_TRY_NUMBER='7' AIRFLOW_CTX_DAG_RUN_ID='scheduled__2024-03-21T15:13:00+00:00'
[2024-03-21T16:51:38.012+0000] {logging_mixin.py:188} INFO - The extract function has been executed and this is data in the next line
[2024-03-21T16:51:38.024+0000] {logging_mixin.py:188} INFO - Initiating the Endpoint...
[2024-03-21T16:51:39.374+0000] {logging_mixin.py:188} INFO - Extracting other available tracks
[2024-03-21T16:52:08.391+0000] {logging_mixin.py:188} INFO - Adding the values of index 0 into the appropriate Keys...
[2024-03-21T22:15:20.779+0000] {taskinstance.py:2731} ERROR - Task failed with exception
Traceback (most recent call last):
  File "/home/airflow/.local/lib/python3.8/site-packages/urllib3/connectionpool.py", line 404, in _make_request
    self._validate_conn(conn)
  File "/home/airflow/.local/lib/python3.8/site-packages/urllib3/connectionpool.py", line 1058, in _validate_conn
    conn.connect()
  File "/home/airflow/.local/lib/python3.8/site-packages/urllib3/connection.py", line 419, in connect
    self.sock = ssl_wrap_socket(
  File "/home/airflow/.local/lib/python3.8/site-packages/urllib3/util/ssl_.py", line 449, in ssl_wrap_socket
    ssl_sock = _ssl_wrap_socket_impl(
  File "/home/airflow/.local/lib/python3.8/site-packages/urllib3/util/ssl_.py", line 493, in _ssl_wrap_socket_impl
    return ssl_context.wrap_socket(sock, server_hostname=server_hostname)
  File "/usr/local/lib/python3.8/ssl.py", line 500, in wrap_socket
    return self.sslsocket_class._create(
  File "/usr/local/lib/python3.8/ssl.py", line 1073, in _create
    self.do_handshake()
  File "/usr/local/lib/python3.8/ssl.py", line 1342, in do_handshake
    self._sslobj.do_handshake()
socket.timeout: _ssl.c:1114: The handshake operation timed out

During handling of the above exception, another exception occurred:

Traceback (most recent call last):
  File "/home/airflow/.local/lib/python3.8/site-packages/requests/adapters.py", line 486, in send
    resp = conn.urlopen(
  File "/home/airflow/.local/lib/python3.8/site-packages/urllib3/connectionpool.py", line 894, in urlopen
    return self.urlopen(
  File "/home/airflow/.local/lib/python3.8/site-packages/urllib3/connectionpool.py", line 799, in urlopen
    retries = retries.increment(
  File "/home/airflow/.local/lib/python3.8/site-packages/urllib3/util/retry.py", line 550, in increment
    raise six.reraise(type(error), error, _stacktrace)
  File "/home/airflow/.local/lib/python3.8/site-packages/urllib3/packages/six.py", line 770, in reraise
    raise value
  File "/home/airflow/.local/lib/python3.8/site-packages/urllib3/connectionpool.py", line 715, in urlopen
    httplib_response = self._make_request(
  File "/home/airflow/.local/lib/python3.8/site-packages/urllib3/connectionpool.py", line 407, in _make_request
    self._raise_timeout(err=e, url=url, timeout_value=conn.timeout)
  File "/home/airflow/.local/lib/python3.8/site-packages/urllib3/connectionpool.py", line 358, in _raise_timeout
    raise ReadTimeoutError(
urllib3.exceptions.ReadTimeoutError: HTTPSConnectionPool(host='api.spotify.com', port=443): Read timed out. (read timeout=5)

During handling of the above exception, another exception occurred:

Traceback (most recent call last):
  File "/home/airflow/.local/lib/python3.8/site-packages/airflow/models/taskinstance.py", line 444, in _execute_task
    result = _execute_callable(context=context, **execute_callable_kwargs)
  File "/home/airflow/.local/lib/python3.8/site-packages/airflow/models/taskinstance.py", line 414, in _execute_callable
    return execute_callable(context=context, **execute_callable_kwargs)
  File "/home/airflow/.local/lib/python3.8/site-packages/airflow/operators/python.py", line 200, in execute
    return_value = self.execute_callable()
  File "/home/airflow/.local/lib/python3.8/site-packages/airflow/operators/python.py", line 217, in execute_callable
    return self.python_callable(*self.op_args, **self.op_kwargs)
  File "/opt/airflow/dags/spotify_to_csvs_to_s3.py", line 110, in Spotify_to_CSV
    data['Artist_Genres'].append(sp.artist(track['artists'][0]['id'])['genres'])
  File "/home/airflow/.local/lib/python3.8/site-packages/spotipy/client.py", line 392, in artist
    return self._get("artists/" + trid)
  File "/home/airflow/.local/lib/python3.8/site-packages/spotipy/client.py", line 323, in _get
    return self._internal_call("GET", url, payload, kwargs)
  File "/home/airflow/.local/lib/python3.8/site-packages/spotipy/client.py", line 266, in _internal_call
    response = self._session.request(
  File "/home/airflow/.local/lib/python3.8/site-packages/requests/sessions.py", line 589, in request
    resp = self.send(prep, **send_kwargs)
  File "/home/airflow/.local/lib/python3.8/site-packages/requests/sessions.py", line 703, in send
    r = adapter.send(request, **kwargs)
  File "/home/airflow/.local/lib/python3.8/site-packages/requests/adapters.py", line 532, in send
    raise ReadTimeout(e, request=request)
requests.exceptions.ReadTimeout: HTTPSConnectionPool(host='api.spotify.com', port=443): Read timed out. (read timeout=5)
[2024-03-21T22:15:20.838+0000] {taskinstance.py:1149} INFO - Marking task as UP_FOR_RETRY. dag_id=spotify_to_s3_data_extraction_v1, task_id=sptoify_to_csv, execution_date=20240321T151300, start_date=20240321T165136, end_date=20240321T221520
[2024-03-21T22:15:20.882+0000] {standard_task_runner.py:107} ERROR - Failed to execute job 644 for task sptoify_to_csv (HTTPSConnectionPool(host='api.spotify.com', port=443): Read timed out. (read timeout=5); 3268)
[2024-03-21T22:15:20.920+0000] {local_task_job_runner.py:234} INFO - Task exited with return code 1
[2024-03-21T22:15:20.990+0000] {taskinstance.py:3312} INFO - 0 downstream tasks scheduled from follow-on schedule check
