[2024-03-21T05:14:24.024+0000] {taskinstance.py:1979} INFO - Dependencies all met for dep_context=non-requeueable deps ti=<TaskInstance: spotify_to_s3_data_extraction_v1.sptoify_to_csv scheduled__2024-03-21T05:08:00+00:00 [queued]>
[2024-03-21T05:14:24.041+0000] {taskinstance.py:1979} INFO - Dependencies all met for dep_context=requeueable deps ti=<TaskInstance: spotify_to_s3_data_extraction_v1.sptoify_to_csv scheduled__2024-03-21T05:08:00+00:00 [queued]>
[2024-03-21T05:14:24.042+0000] {taskinstance.py:2193} INFO - Starting attempt 1 of 6
[2024-03-21T05:14:24.066+0000] {taskinstance.py:2217} INFO - Executing <Task(PythonOperator): sptoify_to_csv> on 2024-03-21 05:08:00+00:00
[2024-03-21T05:14:24.077+0000] {standard_task_runner.py:60} INFO - Started process 1964 to run task
[2024-03-21T05:14:24.083+0000] {standard_task_runner.py:87} INFO - Running: ['***', 'tasks', 'run', 'spotify_to_s3_data_extraction_v1', 'sptoify_to_csv', 'scheduled__2024-03-21T05:08:00+00:00', '--job-id', '365', '--raw', '--subdir', 'DAGS_FOLDER/spotify_to_csvs_to_s3.py', '--cfg-path', '/tmp/tmpvheq4ckc']
[2024-03-21T05:14:24.090+0000] {standard_task_runner.py:88} INFO - Job 365: Subtask sptoify_to_csv
[2024-03-21T05:14:24.192+0000] {task_command.py:423} INFO - Running <TaskInstance: spotify_to_s3_data_extraction_v1.sptoify_to_csv scheduled__2024-03-21T05:08:00+00:00 [running]> on host ca1809388db1
[2024-03-21T05:14:24.341+0000] {taskinstance.py:2513} INFO - Exporting env vars: AIRFLOW_CTX_DAG_OWNER='Nathaniel Solomon' AIRFLOW_CTX_DAG_ID='spotify_to_s3_data_extraction_v1' AIRFLOW_CTX_TASK_ID='sptoify_to_csv' AIRFLOW_CTX_EXECUTION_DATE='2024-03-21T05:08:00+00:00' AIRFLOW_CTX_TRY_NUMBER='1' AIRFLOW_CTX_DAG_RUN_ID='scheduled__2024-03-21T05:08:00+00:00'
[2024-03-21T05:14:24.344+0000] {logging_mixin.py:188} INFO - The extract function has been executed and this is data in the next line
[2024-03-21T05:14:24.345+0000] {logging_mixin.py:188} INFO - Initiating the Endpoint...
[2024-03-21T05:14:24.361+0000] {connectionpool.py:824} WARNING - Retrying (Retry(total=2, connect=None, read=False, redirect=None, status=3)) after connection broken by 'NewConnectionError('<urllib3.connection.HTTPSConnection object at 0x7f18ac8ff6a0>: Failed to establish a new connection: [Errno -2] Name or service not known')': /v1/search?q=year%3A2024&limit=50&offset=0&type=track&market=US
[2024-03-21T05:14:24.973+0000] {connectionpool.py:824} WARNING - Retrying (Retry(total=1, connect=None, read=False, redirect=None, status=3)) after connection broken by 'NewConnectionError('<urllib3.connection.HTTPSConnection object at 0x7f18ac8ff850>: Failed to establish a new connection: [Errno -2] Name or service not known')': /v1/search?q=year%3A2024&limit=50&offset=0&type=track&market=US
[2024-03-21T05:14:26.186+0000] {connectionpool.py:824} WARNING - Retrying (Retry(total=0, connect=None, read=False, redirect=None, status=3)) after connection broken by 'NewConnectionError('<urllib3.connection.HTTPSConnection object at 0x7f18ac8ff910>: Failed to establish a new connection: [Errno -2] Name or service not known')': /v1/search?q=year%3A2024&limit=50&offset=0&type=track&market=US
[2024-03-21T05:14:26.194+0000] {taskinstance.py:2731} ERROR - Task failed with exception
Traceback (most recent call last):
  File "/home/airflow/.local/lib/python3.8/site-packages/urllib3/connection.py", line 174, in _new_conn
    conn = connection.create_connection(
  File "/home/airflow/.local/lib/python3.8/site-packages/urllib3/util/connection.py", line 72, in create_connection
    for res in socket.getaddrinfo(host, port, family, socket.SOCK_STREAM):
  File "/usr/local/lib/python3.8/socket.py", line 918, in getaddrinfo
    for res in _socket.getaddrinfo(host, port, family, type, proto, flags):
socket.gaierror: [Errno -2] Name or service not known

During handling of the above exception, another exception occurred:

Traceback (most recent call last):
  File "/home/airflow/.local/lib/python3.8/site-packages/urllib3/connectionpool.py", line 715, in urlopen
    httplib_response = self._make_request(
  File "/home/airflow/.local/lib/python3.8/site-packages/urllib3/connectionpool.py", line 404, in _make_request
    self._validate_conn(conn)
  File "/home/airflow/.local/lib/python3.8/site-packages/urllib3/connectionpool.py", line 1058, in _validate_conn
    conn.connect()
  File "/home/airflow/.local/lib/python3.8/site-packages/urllib3/connection.py", line 363, in connect
    self.sock = conn = self._new_conn()
  File "/home/airflow/.local/lib/python3.8/site-packages/urllib3/connection.py", line 186, in _new_conn
    raise NewConnectionError(
urllib3.exceptions.NewConnectionError: <urllib3.connection.HTTPSConnection object at 0x7f18ac8ffd60>: Failed to establish a new connection: [Errno -2] Name or service not known

During handling of the above exception, another exception occurred:

Traceback (most recent call last):
  File "/home/airflow/.local/lib/python3.8/site-packages/requests/adapters.py", line 486, in send
    resp = conn.urlopen(
  File "/home/airflow/.local/lib/python3.8/site-packages/urllib3/connectionpool.py", line 827, in urlopen
    return self.urlopen(
  File "/home/airflow/.local/lib/python3.8/site-packages/urllib3/connectionpool.py", line 827, in urlopen
    return self.urlopen(
  File "/home/airflow/.local/lib/python3.8/site-packages/urllib3/connectionpool.py", line 827, in urlopen
    return self.urlopen(
  File "/home/airflow/.local/lib/python3.8/site-packages/urllib3/connectionpool.py", line 799, in urlopen
    retries = retries.increment(
  File "/home/airflow/.local/lib/python3.8/site-packages/urllib3/util/retry.py", line 592, in increment
    raise MaxRetryError(_pool, url, error or ResponseError(cause))
urllib3.exceptions.MaxRetryError: HTTPSConnectionPool(host='api.spotify.com', port=443): Max retries exceeded with url: /v1/search?q=year%3A2024&limit=50&offset=0&type=track&market=US (Caused by NewConnectionError('<urllib3.connection.HTTPSConnection object at 0x7f18ac8ffd60>: Failed to establish a new connection: [Errno -2] Name or service not known'))

During handling of the above exception, another exception occurred:

Traceback (most recent call last):
  File "/home/airflow/.local/lib/python3.8/site-packages/airflow/models/taskinstance.py", line 444, in _execute_task
    result = _execute_callable(context=context, **execute_callable_kwargs)
  File "/home/airflow/.local/lib/python3.8/site-packages/airflow/models/taskinstance.py", line 414, in _execute_callable
    return execute_callable(context=context, **execute_callable_kwargs)
  File "/home/airflow/.local/lib/python3.8/site-packages/airflow/operators/python.py", line 200, in execute
    return_value = self.execute_callable()
  File "/home/airflow/.local/lib/python3.8/site-packages/airflow/operators/python.py", line 217, in execute_callable
    return self.python_callable(*self.op_args, **self.op_kwargs)
  File "/opt/airflow/dags/spotify_to_csvs_to_s3.py", line 58, in Spotify_to_CSV
    top_tracks = sp.search(q='year:2024', type='track', limit=50, market='US')
  File "/home/airflow/.local/lib/python3.8/site-packages/spotipy/client.py", line 587, in search
    return self._get(
  File "/home/airflow/.local/lib/python3.8/site-packages/spotipy/client.py", line 323, in _get
    return self._internal_call("GET", url, payload, kwargs)
  File "/home/airflow/.local/lib/python3.8/site-packages/spotipy/client.py", line 266, in _internal_call
    response = self._session.request(
  File "/home/airflow/.local/lib/python3.8/site-packages/requests/sessions.py", line 589, in request
    resp = self.send(prep, **send_kwargs)
  File "/home/airflow/.local/lib/python3.8/site-packages/requests/sessions.py", line 703, in send
    r = adapter.send(request, **kwargs)
  File "/home/airflow/.local/lib/python3.8/site-packages/requests/adapters.py", line 519, in send
    raise ConnectionError(e, request=request)
requests.exceptions.ConnectionError: HTTPSConnectionPool(host='api.spotify.com', port=443): Max retries exceeded with url: /v1/search?q=year%3A2024&limit=50&offset=0&type=track&market=US (Caused by NewConnectionError('<urllib3.connection.HTTPSConnection object at 0x7f18ac8ffd60>: Failed to establish a new connection: [Errno -2] Name or service not known'))
[2024-03-21T05:14:26.210+0000] {taskinstance.py:1149} INFO - Marking task as UP_FOR_RETRY. dag_id=spotify_to_s3_data_extraction_v1, task_id=sptoify_to_csv, execution_date=20240321T050800, start_date=20240321T051424, end_date=20240321T051426
[2024-03-21T05:14:26.230+0000] {standard_task_runner.py:107} ERROR - Failed to execute job 365 for task sptoify_to_csv (HTTPSConnectionPool(host='api.spotify.com', port=443): Max retries exceeded with url: /v1/search?q=year%3A2024&limit=50&offset=0&type=track&market=US (Caused by NewConnectionError('<urllib3.connection.HTTPSConnection object at 0x7f18ac8ffd60>: Failed to establish a new connection: [Errno -2] Name or service not known')); 1964)
[2024-03-21T05:14:26.283+0000] {local_task_job_runner.py:234} INFO - Task exited with return code 1
[2024-03-21T05:14:26.323+0000] {taskinstance.py:3312} INFO - 0 downstream tasks scheduled from follow-on schedule check
