[2024-03-22T00:17:43.021+0000] {taskinstance.py:1979} INFO - Dependencies all met for dep_context=non-requeueable deps ti=<TaskInstance: spotify_to_s3_data_extraction_v1.sptoify_to_csv scheduled__2024-03-21T07:32:00+00:00 [queued]>
[2024-03-22T00:17:43.079+0000] {taskinstance.py:1979} INFO - Dependencies all met for dep_context=requeueable deps ti=<TaskInstance: spotify_to_s3_data_extraction_v1.sptoify_to_csv scheduled__2024-03-21T07:32:00+00:00 [queued]>
[2024-03-22T00:17:43.085+0000] {taskinstance.py:2193} INFO - Starting attempt 10 of 10
[2024-03-22T00:17:43.133+0000] {taskinstance.py:2217} INFO - Executing <Task(PythonOperator): sptoify_to_csv> on 2024-03-21 07:32:00+00:00
[2024-03-22T00:17:43.149+0000] {standard_task_runner.py:60} INFO - Started process 3952 to run task
[2024-03-22T00:17:43.175+0000] {standard_task_runner.py:87} INFO - Running: ['***', 'tasks', 'run', 'spotify_to_s3_data_extraction_v1', 'sptoify_to_csv', 'scheduled__2024-03-21T07:32:00+00:00', '--job-id', '727', '--raw', '--subdir', 'DAGS_FOLDER/spotify_to_csvs_to_s3.py', '--cfg-path', '/tmp/tmpnmz6ynx0']
[2024-03-22T00:17:43.184+0000] {standard_task_runner.py:88} INFO - Job 727: Subtask sptoify_to_csv
[2024-03-22T00:17:43.409+0000] {task_command.py:423} INFO - Running <TaskInstance: spotify_to_s3_data_extraction_v1.sptoify_to_csv scheduled__2024-03-21T07:32:00+00:00 [running]> on host ca1809388db1
[2024-03-22T00:17:43.616+0000] {taskinstance.py:2513} INFO - Exporting env vars: AIRFLOW_CTX_DAG_OWNER='Nathaniel Solomon' AIRFLOW_CTX_DAG_ID='spotify_to_s3_data_extraction_v1' AIRFLOW_CTX_TASK_ID='sptoify_to_csv' AIRFLOW_CTX_EXECUTION_DATE='2024-03-21T07:32:00+00:00' AIRFLOW_CTX_TRY_NUMBER='10' AIRFLOW_CTX_DAG_RUN_ID='scheduled__2024-03-21T07:32:00+00:00'
[2024-03-22T00:17:43.623+0000] {logging_mixin.py:188} INFO - The extract function has been executed and this is data in the next line
[2024-03-22T00:17:43.625+0000] {logging_mixin.py:188} INFO - Initiating the Endpoint...
[2024-03-22T00:17:43.653+0000] {taskinstance.py:2731} ERROR - Task failed with exception
Traceback (most recent call last):
  File "/home/airflow/.local/lib/python3.8/site-packages/urllib3/connection.py", line 174, in _new_conn
    conn = connection.create_connection(
  File "/home/airflow/.local/lib/python3.8/site-packages/urllib3/util/connection.py", line 72, in create_connection
    for res in socket.getaddrinfo(host, port, family, socket.SOCK_STREAM):
  File "/usr/local/lib/python3.8/socket.py", line 918, in getaddrinfo
    for res in _socket.getaddrinfo(host, port, family, type, proto, flags):
socket.gaierror: [Errno -2] Name or service not known

During handling of the above exception, another exception occurred:

Traceback (most recent call last):
  File "/home/airflow/.local/lib/python3.8/site-packages/urllib3/connectionpool.py", line 715, in urlopen
    httplib_response = self._make_request(
  File "/home/airflow/.local/lib/python3.8/site-packages/urllib3/connectionpool.py", line 404, in _make_request
    self._validate_conn(conn)
  File "/home/airflow/.local/lib/python3.8/site-packages/urllib3/connectionpool.py", line 1058, in _validate_conn
    conn.connect()
  File "/home/airflow/.local/lib/python3.8/site-packages/urllib3/connection.py", line 363, in connect
    self.sock = conn = self._new_conn()
  File "/home/airflow/.local/lib/python3.8/site-packages/urllib3/connection.py", line 186, in _new_conn
    raise NewConnectionError(
urllib3.exceptions.NewConnectionError: <urllib3.connection.HTTPSConnection object at 0x7f18ac905c40>: Failed to establish a new connection: [Errno -2] Name or service not known

During handling of the above exception, another exception occurred:

Traceback (most recent call last):
  File "/home/airflow/.local/lib/python3.8/site-packages/requests/adapters.py", line 486, in send
    resp = conn.urlopen(
  File "/home/airflow/.local/lib/python3.8/site-packages/urllib3/connectionpool.py", line 799, in urlopen
    retries = retries.increment(
  File "/home/airflow/.local/lib/python3.8/site-packages/urllib3/util/retry.py", line 592, in increment
    raise MaxRetryError(_pool, url, error or ResponseError(cause))
urllib3.exceptions.MaxRetryError: HTTPSConnectionPool(host='accounts.spotify.com', port=443): Max retries exceeded with url: /api/token (Caused by NewConnectionError('<urllib3.connection.HTTPSConnection object at 0x7f18ac905c40>: Failed to establish a new connection: [Errno -2] Name or service not known'))

During handling of the above exception, another exception occurred:

Traceback (most recent call last):
  File "/home/airflow/.local/lib/python3.8/site-packages/airflow/models/taskinstance.py", line 444, in _execute_task
    result = _execute_callable(context=context, **execute_callable_kwargs)
  File "/home/airflow/.local/lib/python3.8/site-packages/airflow/models/taskinstance.py", line 414, in _execute_callable
    return execute_callable(context=context, **execute_callable_kwargs)
  File "/home/airflow/.local/lib/python3.8/site-packages/airflow/operators/python.py", line 200, in execute
    return_value = self.execute_callable()
  File "/home/airflow/.local/lib/python3.8/site-packages/airflow/operators/python.py", line 217, in execute_callable
    return self.python_callable(*self.op_args, **self.op_kwargs)
  File "/opt/airflow/dags/spotify_to_csvs_to_s3.py", line 58, in Spotify_to_CSV
    top_tracks = sp.search(q='year:2024', type='track', limit=50, market='US')
  File "/home/airflow/.local/lib/python3.8/site-packages/spotipy/client.py", line 587, in search
    return self._get(
  File "/home/airflow/.local/lib/python3.8/site-packages/spotipy/client.py", line 323, in _get
    return self._internal_call("GET", url, payload, kwargs)
  File "/home/airflow/.local/lib/python3.8/site-packages/spotipy/client.py", line 247, in _internal_call
    headers = self._auth_headers()
  File "/home/airflow/.local/lib/python3.8/site-packages/spotipy/client.py", line 238, in _auth_headers
    token = self.auth_manager.get_access_token(as_dict=False)
  File "/home/airflow/.local/lib/python3.8/site-packages/spotipy/oauth2.py", line 238, in get_access_token
    token_info = self._request_access_token()
  File "/home/airflow/.local/lib/python3.8/site-packages/spotipy/oauth2.py", line 257, in _request_access_token
    response = self._session.post(
  File "/home/airflow/.local/lib/python3.8/site-packages/requests/sessions.py", line 637, in post
    return self.request("POST", url, data=data, json=json, **kwargs)
  File "/home/airflow/.local/lib/python3.8/site-packages/requests/sessions.py", line 589, in request
    resp = self.send(prep, **send_kwargs)
  File "/home/airflow/.local/lib/python3.8/site-packages/requests/sessions.py", line 703, in send
    r = adapter.send(request, **kwargs)
  File "/home/airflow/.local/lib/python3.8/site-packages/requests/adapters.py", line 519, in send
    raise ConnectionError(e, request=request)
requests.exceptions.ConnectionError: HTTPSConnectionPool(host='accounts.spotify.com', port=443): Max retries exceeded with url: /api/token (Caused by NewConnectionError('<urllib3.connection.HTTPSConnection object at 0x7f18ac905c40>: Failed to establish a new connection: [Errno -2] Name or service not known'))
[2024-03-22T00:17:43.681+0000] {taskinstance.py:1149} INFO - Marking task as FAILED. dag_id=spotify_to_s3_data_extraction_v1, task_id=sptoify_to_csv, execution_date=20240321T073200, start_date=20240322T001743, end_date=20240322T001743
[2024-03-22T00:17:43.704+0000] {standard_task_runner.py:107} ERROR - Failed to execute job 727 for task sptoify_to_csv (HTTPSConnectionPool(host='accounts.spotify.com', port=443): Max retries exceeded with url: /api/token (Caused by NewConnectionError('<urllib3.connection.HTTPSConnection object at 0x7f18ac905c40>: Failed to establish a new connection: [Errno -2] Name or service not known')); 3952)
[2024-03-22T00:17:43.728+0000] {local_task_job_runner.py:234} INFO - Task exited with return code 1
[2024-03-22T00:17:43.966+0000] {taskinstance.py:3312} INFO - 0 downstream tasks scheduled from follow-on schedule check
