[2024-03-21T04:32:34.599+0000] {taskinstance.py:1979} INFO - Dependencies all met for dep_context=non-requeueable deps ti=<TaskInstance: spotify_to_s3_data_extraction_v1.sptoify_to_csv scheduled__2024-03-21T04:31:00+00:00 [queued]>
[2024-03-21T04:32:34.863+0000] {taskinstance.py:1979} INFO - Dependencies all met for dep_context=requeueable deps ti=<TaskInstance: spotify_to_s3_data_extraction_v1.sptoify_to_csv scheduled__2024-03-21T04:31:00+00:00 [queued]>
[2024-03-21T04:32:34.873+0000] {taskinstance.py:2193} INFO - Starting attempt 1 of 6
[2024-03-21T04:32:35.183+0000] {taskinstance.py:2217} INFO - Executing <Task(PythonOperator): sptoify_to_csv> on 2024-03-21 04:31:00+00:00
[2024-03-21T04:32:35.418+0000] {standard_task_runner.py:60} INFO - Started process 1838 to run task
[2024-03-21T04:32:35.583+0000] {standard_task_runner.py:87} INFO - Running: ['***', 'tasks', 'run', 'spotify_to_s3_data_extraction_v1', 'sptoify_to_csv', 'scheduled__2024-03-21T04:31:00+00:00', '--job-id', '344', '--raw', '--subdir', 'DAGS_FOLDER/spotify_to_csvs_to_s3.py', '--cfg-path', '/tmp/tmp_4oiwdkn']
[2024-03-21T04:32:35.758+0000] {standard_task_runner.py:88} INFO - Job 344: Subtask sptoify_to_csv
[2024-03-21T04:32:37.402+0000] {task_command.py:423} INFO - Running <TaskInstance: spotify_to_s3_data_extraction_v1.sptoify_to_csv scheduled__2024-03-21T04:31:00+00:00 [running]> on host ca1809388db1
[2024-03-21T04:32:38.026+0000] {taskinstance.py:2513} INFO - Exporting env vars: AIRFLOW_CTX_DAG_OWNER='Nathaniel Solomon' AIRFLOW_CTX_DAG_ID='spotify_to_s3_data_extraction_v1' AIRFLOW_CTX_TASK_ID='sptoify_to_csv' AIRFLOW_CTX_EXECUTION_DATE='2024-03-21T04:31:00+00:00' AIRFLOW_CTX_TRY_NUMBER='1' AIRFLOW_CTX_DAG_RUN_ID='scheduled__2024-03-21T04:31:00+00:00'
[2024-03-21T04:32:38.040+0000] {logging_mixin.py:188} INFO - The extract function has been executed and this is data in the next line
[2024-03-21T04:32:38.043+0000] {logging_mixin.py:188} INFO - Initiating the Endpoint...
[2024-03-21T04:32:39.249+0000] {logging_mixin.py:188} INFO - Extracting other available tracks
[2024-03-21T04:46:13.938+0000] {taskinstance.py:2731} ERROR - Task failed with exception
Traceback (most recent call last):
  File "/home/airflow/.local/lib/python3.8/site-packages/urllib3/connectionpool.py", line 715, in urlopen
    httplib_response = self._make_request(
  File "/home/airflow/.local/lib/python3.8/site-packages/urllib3/connectionpool.py", line 467, in _make_request
    six.raise_from(e, None)
  File "<string>", line 3, in raise_from
  File "/home/airflow/.local/lib/python3.8/site-packages/urllib3/connectionpool.py", line 462, in _make_request
    httplib_response = conn.getresponse()
  File "/usr/local/lib/python3.8/http/client.py", line 1348, in getresponse
    response.begin()
  File "/usr/local/lib/python3.8/http/client.py", line 316, in begin
    version, status, reason = self._read_status()
  File "/usr/local/lib/python3.8/http/client.py", line 285, in _read_status
    raise RemoteDisconnected("Remote end closed connection without"
http.client.RemoteDisconnected: Remote end closed connection without response

During handling of the above exception, another exception occurred:

Traceback (most recent call last):
  File "/home/airflow/.local/lib/python3.8/site-packages/requests/adapters.py", line 486, in send
    resp = conn.urlopen(
  File "/home/airflow/.local/lib/python3.8/site-packages/urllib3/connectionpool.py", line 799, in urlopen
    retries = retries.increment(
  File "/home/airflow/.local/lib/python3.8/site-packages/urllib3/util/retry.py", line 550, in increment
    raise six.reraise(type(error), error, _stacktrace)
  File "/home/airflow/.local/lib/python3.8/site-packages/urllib3/packages/six.py", line 769, in reraise
    raise value.with_traceback(tb)
  File "/home/airflow/.local/lib/python3.8/site-packages/urllib3/connectionpool.py", line 715, in urlopen
    httplib_response = self._make_request(
  File "/home/airflow/.local/lib/python3.8/site-packages/urllib3/connectionpool.py", line 467, in _make_request
    six.raise_from(e, None)
  File "<string>", line 3, in raise_from
  File "/home/airflow/.local/lib/python3.8/site-packages/urllib3/connectionpool.py", line 462, in _make_request
    httplib_response = conn.getresponse()
  File "/usr/local/lib/python3.8/http/client.py", line 1348, in getresponse
    response.begin()
  File "/usr/local/lib/python3.8/http/client.py", line 316, in begin
    version, status, reason = self._read_status()
  File "/usr/local/lib/python3.8/http/client.py", line 285, in _read_status
    raise RemoteDisconnected("Remote end closed connection without"
urllib3.exceptions.ProtocolError: ('Connection aborted.', RemoteDisconnected('Remote end closed connection without response'))

During handling of the above exception, another exception occurred:

Traceback (most recent call last):
  File "/home/airflow/.local/lib/python3.8/site-packages/airflow/models/taskinstance.py", line 444, in _execute_task
    result = _execute_callable(context=context, **execute_callable_kwargs)
  File "/home/airflow/.local/lib/python3.8/site-packages/airflow/models/taskinstance.py", line 414, in _execute_callable
    return execute_callable(context=context, **execute_callable_kwargs)
  File "/home/airflow/.local/lib/python3.8/site-packages/airflow/operators/python.py", line 200, in execute
    return_value = self.execute_callable()
  File "/home/airflow/.local/lib/python3.8/site-packages/airflow/operators/python.py", line 217, in execute_callable
    return self.python_callable(*self.op_args, **self.op_kwargs)
  File "/opt/airflow/dags/spotify_to_csvs_to_s3.py", line 64, in Spotify_to_CSV
    top_tracks = sp.next(top_tracks['tracks'])
  File "/home/airflow/.local/lib/python3.8/site-packages/spotipy/client.py", line 347, in next
    return self._get(result["next"])
  File "/home/airflow/.local/lib/python3.8/site-packages/spotipy/client.py", line 323, in _get
    return self._internal_call("GET", url, payload, kwargs)
  File "/home/airflow/.local/lib/python3.8/site-packages/spotipy/client.py", line 266, in _internal_call
    response = self._session.request(
  File "/home/airflow/.local/lib/python3.8/site-packages/requests/sessions.py", line 589, in request
    resp = self.send(prep, **send_kwargs)
  File "/home/airflow/.local/lib/python3.8/site-packages/requests/sessions.py", line 703, in send
    r = adapter.send(request, **kwargs)
  File "/home/airflow/.local/lib/python3.8/site-packages/requests/adapters.py", line 501, in send
    raise ConnectionError(err, request=request)
requests.exceptions.ConnectionError: ('Connection aborted.', RemoteDisconnected('Remote end closed connection without response'))
[2024-03-21T04:46:14.029+0000] {taskinstance.py:1149} INFO - Marking task as UP_FOR_RETRY. dag_id=spotify_to_s3_data_extraction_v1, task_id=sptoify_to_csv, execution_date=20240321T043100, start_date=20240321T043234, end_date=20240321T044614
[2024-03-21T04:46:14.106+0000] {standard_task_runner.py:107} ERROR - Failed to execute job 344 for task sptoify_to_csv (('Connection aborted.', RemoteDisconnected('Remote end closed connection without response')); 1838)
[2024-03-21T04:46:14.179+0000] {local_task_job_runner.py:234} INFO - Task exited with return code 1
[2024-03-21T04:46:14.219+0000] {taskinstance.py:3312} INFO - 0 downstream tasks scheduled from follow-on schedule check
